Workbook

Sheet Instrucciones
B1: PLAN MAESTRO DE MANTENIMIENTO Y CALIBRACIÓN — Guía de uso | G1: Código: COP15-F11 Revisión: 03 Fecha de emisión: 15/07/2026
B3: 1. OBJETIVO | C3: Establecer la programación, ejecución y registro de las actividades de mantenimiento preventivo y del plan anual de calibración de los equipos e instrumentos de los laboratorios, asegurando su disponibilidad, confiabilidad y trazabilidad metrológica.
B4: 2. ALCANCE | C4: Aplica a todos los equipos e instrumentos registrados en la hoja EQUIPOS de los laboratorios de Materiales, Emisiones y Calibración.
B5: 3. RESPONSABILIDADES | C5: El responsable de cada laboratorio mantiene actualizado el registro de equipos, actividades e historial. El área de Calibración da seguimiento a los vencimientos indicados por el semáforo y gestiona los servicios con proveedores externos. Todo equipo con calibración vencida debe identificarse como NO OPERABLE hasta su recalibración.
B6: 4. DESARROLLO
B7: 4.1 EQUIPOS | C7: Registrar cada equipo una sola vez: ID, nombre, laboratorio al que pertenece (lista desplegable: Materiales / Emisiones / Calibración), marca, modelo, serie y estatus. La columna '¿Requiere calibración?' se calcula automáticamente a partir de la hoja CALIBRACIÓN.
B8: 4.2 ACTIVIDADES | C8: Definir cada actividad de mantenimiento preventivo: equipo (lista desplegable), descripción, frecuencia y semana de inicio. Con estos datos el Plan Maestro se genera automáticamente.
B9: 4.3 PLAN MAESTRO | C9: Matriz automática de 52 semanas. No se captura manualmente: modificar únicamente el AÑO (celda amarilla). 'P' indica semana planeada; '✓' aparece al registrar la ejecución en HISTORIAL. Las celdas en rojo indican actividades vencidas.
B10: 4.4 HISTORIAL | C10: Registro permanente de los mantenimientos ejecutados: fecha, equipo, actividad, ejecutante y horas. Este registro alimenta el Plan Maestro y el Dashboard, y se conserva entre años.
B11: 4.5 CALIBRACIÓN | C11: Plan anual de calibración por equipo y magnitud. Indica si el instrumento requiere calibración, quién la realiza (proveedor), trazabilidad, última calibración y vencimiento. El semáforo se calcula automáticamente. Al recibir un certificado, actualizar la fecha de última calibración y el número de certificado, y archivar el PDF en las carpetas '0X. Calibraciones' (encriptados) y '02. Calibraciones' (no encriptados).
B12: 4.6 DASHBOARD | C12: Indicadores automáticos de cumplimiento de mantenimiento y estado de calibraciones. No editar.
B14: 5. CÓDIGO DE COLORES
C15: Celda amarilla: dato capturado por el usuario
C16: Celda gris: dato fijo o fórmula automática — no modificar
C17: Verde: calibración vigente / dentro de periodo
C18: Naranja: por vencer (60 días o menos) — programar servicio
C19: Rojo: vencido — identificar el equipo como NO OPERABLE
C20: P: semana con mantenimiento planeado
C21: ✓: mantenimiento realizado (registrado en Historial)

Sheet Equipos
B1: REGISTRO DE EQUIPOS | H1: Código: COP15-F11 Revisión: 03 Fecha de emisión: 15/07/2026
A2: ID | B2: Equipo | C2: Laboratorio | D2: Marca | E2: Modelo | F2: No. Serie | G2: Estatus | H2: ¿Requiere calibración? (auto) | I2: Cal. vencidas (auto) | J2: Notas
A3: E-001 | B3: HVAC | C3: Emisiones | D3: Kimo | E3: Varios (ver Calibración) | F3: 2F150708994 | G3: Activo | H3: =IF($B3="","",IF(COUNTIFS(Calibración!$B$3:$B$152,$B3,Calibración!$I$3:$I$152,"Sí")>0,"Sí","No")) -> Sí | I3: =IF($B3="","",COUNTIFS(Calibración!$B$3:$B$152,$B3,Calibración!$Q$3:$Q$152,"VENCIDO")) -> 2
A4: E-002 | B4: VETS | C4: Emisiones | D4: Vaisala | E4: INDIGO520 | F4: Varios | G4: Activo | H4: =IF($B4="","",IF(COUNTIFS(Calibración!$B$3:$B$152,$B4,Calibración!$I$3:$I$152,"Sí")>0,"Sí","No")) -> Sí | I4: =IF($B4="","",COUNTIFS(Calibración!$B$3:$B$152,$B4,Calibración!$Q$3:$Q$152,"VENCIDO")) -> 6
A5: E-003 | B5: Clean Cham | C5: Emisiones | D5: Shynyei | E5: Varios (ver Calibración) | F5: Varios | G5: Activo | H5: =IF($B5="","",IF(COUNTIFS(Calibración!$B$3:$B$152,$B5,Calibración!$I$3:$I$152,"Sí")>0,"Sí","No")) -> Sí | I5: =IF($B5="","",COUNTIFS(Calibración!$B$3:$B$152,$B5,Calibración!$Q$3:$Q$152,"VENCIDO")) -> 3
A6: E-004 | B6: CFO | C6: Emisiones | D6: Horiba | E6: 5102514973 | F6: 7005035500 | G6: Activo | H6: =IF($B6="","",IF(COUNTIFS(Calibración!$B$3:$B$152,$B6,Calibración!$I$3:$I$152,"Sí")>0,"Sí","No")) -> Sí | I6: =IF($B6="","",COUNTIFS(Calibración!$B$3:$B$152,$B6,Calibración!$Q$3:$Q$152,"VENCIDO")) -> 1
A7: E-005 | B7: CPC-100 | C7: Emisiones | D7: Horiba | E7: CPC-100 | F7: C100152302 | G7: Activo | H7: =IF($B7="","",IF(COUNTIFS(Calibración!$B$3:$B$152,$B7,Calibración!$I$3:$I$152,"Sí")>0,"Sí","No")) -> Sí | I7: =IF($B7="","",COUNTIFS(Calibración!$B$3:$B$152,$B7,Calibración!$Q$3:$Q$152,"VENCIDO")) -> 0
A8: E-006 | B8: Rack | C8: Emisiones | D8: Horiba | E8: Rack con venturi | F8: 69161 | G8: Activo | H8: =IF($B8="","",IF(COUNTIFS(Calibración!$B$3:$B$152,$B8,Calibración!$I$3:$I$152,"Sí")>0,"Sí","No")) -> Sí | I8: =IF($B8="","",COUNTIFS(Calibración!$B$3:$B$152,$B8,Calibración!$Q$3:$Q$152,"VENCIDO")) -> 1
A9: E-007 | B9: Venturi | C9: Emisiones | D9: Horiba | E9: cilindro venturi | F9: 69015 | G9: Activo | H9: =IF($B9="","",IF(COUNTIFS(Calibración!$B$3:$B$152,$B9,Calibración!$I$3:$I$152,"Sí")>0,"Sí","No")) -> Sí | I9: =IF($B9="","",COUNTIFS(Calibración!$B$3:$B$152,$B9,Calibración!$Q$3:$Q$152,"VENCIDO")) -> 1
A10: E-008 | B10: GDC | C10: Emisiones | D10: Horiba | E10: ONE | F10: S2001362117000020 | G10: Activo | H10: =IF($B10="","",IF(COUNTIFS(Calibración!$B$3:$B$152,$B10,Calibración!$I$3:$I$152,"Sí")>0,"Sí","No")) -> Sí | I10: =IF($B10="","",COUNTIFS(Calibración!$B$3:$B$152,$B10,Calibración!$Q$3:$Q$152,"VENCIDO")) -> 0
A11: E-009 | B11: Bubbler | C11: Emisiones | D11: Horiba | E11: Heated Bubler | F11: 8001005048 | G11: Activo | H11: =IF($B11="","",IF(COUNTIFS(Calibración!$B$3:$B$152,$B11,Calibración!$I$3:$I$152,"Sí")>0,"Sí","No")) -> Sí | I11: =IF($B11="","",COUNTIFS(Calibración!$B$3:$B$152,$B11,Calibración!$Q$3:$Q$152,"VENCIDO")) -> 1
A12: E-010 | B12: RMT1-TS | C12: Emisiones | E12: S1-8 | G12: Activo | H12: =IF($B12="","",IF(COUNTIFS(Calibración!$B$3:$B$152,$B12,Calibración!$I$3:$I$152,"Sí")>0,"Sí","No")) -> Sí | I12: =IF($B12="","",COUNTIFS(Calibración!$B$3:$B$152,$B12,Calibración!$Q$3:$Q$152,"VENCIDO")) -> 0
A13: E-011 | B13: Manometer 1 | C13: Emisiones | D13: ManoStar | E13: WO801 | G13: Activo | H13: =IF($B13="","",IF(COUNTIFS(Calibración!$B$3:$B$152,$B13,Calibración!$I$3:$I$152,"Sí")>0,"Sí","No")) -> Sí | I13: =IF($B13="","",COUNTIFS(Calibración!$B$3:$B$152,$B13,Calibración!$Q$3:$Q$152,"VENCIDO")) -> 0
A14: E-012 | B14: Manometer 2 | C14: Emisiones | D14: ManoStar | E14: WO81 | G14: Activo | H14: =IF($B14="","",IF(COUNTIFS(Calibración!$B$3:$B$152,$B14,Calibración!$I$3:$I$152,"Sí")>0,"Sí","No")) -> Sí | I14: =IF($B14="","",COUNTIFS(Calibración!$B$3:$B$152,$B14,Calibración!$Q$3:$Q$152,"VENCIDO")) -> 0
A15: E-013 | B15: Dynamometer | C15: Emisiones | D15: A&G | E15: Varios (ver Calibración) | F15: Varios | G15: Activo | H15: =IF($B15="","",IF(COUNTIFS(Calibración!$B$3:$B$152,$B15,Calibración!$I$3:$I$152,"Sí")>0,"Sí","No")) -> Sí | I15: =IF($B15="","",COUNTIFS(Calibración!$B$3:$B$152,$B15,Calibración!$Q$3:$Q$152,"VENCIDO")) -> 1
A16: E-014 | B16: Laboratorio | C16: Emisiones | D16: FLUKE | E16: Varios (ver Calibración) | F16: Varios | G16: Activo | H16: =IF($B16="","",IF(COUNTIFS(Calibración!$B$3:$B$152,$B16,Calibración!$I$3:$I$152,"Sí")>0,"Sí","No")) -> Sí | I16: =IF($B16="","",COUNTIFS(Calibración!$B$3:$B$152,$B16,Calibración!$Q$3:$Q$152,"VENCIDO")) -> 0
H17: =IF($B17="","",IF(COUNTIFS(Calibración!$B$3:$B$152,$B17,Calibración!$I$3:$I$152,"Sí")>0,"Sí","No")) | I17: =IF($B17="","",COUNTIFS(Calibración!$B$3:$B$152,$B17,Calibración!$Q$3:$Q$152,"VENCIDO"))
H18: =IF($B18="","",IF(COUNTIFS(Calibración!$B$3:$B$152,$B18,Calibración!$I$3:$I$152,"Sí")>0,"Sí","No")) | I18: =IF($B18="","",COUNTIFS(Calibración!$B$3:$B$152,$B18,Calibración!$Q$3:$Q$152,"VENCIDO"))
H19: =IF($B19="","",IF(COUNTIFS(Calibración!$B$3:$B$152,$B19,Calibración!$I$3:$I$152,"Sí")>0,"Sí","No")) | I19: =IF($B19="","",COUNTIFS(Calibración!$B$3:$B$152,$B19,Calibración!$Q$3:$Q$152,"VENCIDO"))
H20: =IF($B20="","",IF(COUNTIFS(Calibración!$B$3:$B$152,$B20,Calibración!$I$3:$I$152,"Sí")>0,"Sí","No")) | I20: =IF($B20="","",COUNTIFS(Calibración!$B$3:$B$152,$B20,Calibración!$Q$3:$Q$152,"VENCIDO"))
H21: =IF($B21="","",IF(COUNTIFS(Calibración!$B$3:$B$152,$B21,Calibración!$I$3:$I$152,"Sí")>0,"Sí","No")) | I21: =IF($B21="","",COUNTIFS(Calibración!$B$3:$B$152,$B21,Calibración!$Q$3:$Q$152,"VENCIDO"))
H22: =IF($B22="","",IF(COUNTIFS(Calibración!$B$3:$B$152,$B22,Calibración!$I$3:$I$152,"Sí")>0,"Sí","No")) | I22: =IF($B22="","",COUNTIFS(Calibración!$B$3:$B$152,$B22,Calibración!$Q$3:$Q$152,"VENCIDO"))
H23: =IF($B23="","",IF(COUNTIFS(Calibración!$B$3:$B$152,$B23,Calibración!$I$3:$I$152,"Sí")>0,"Sí","No")) | I23: =IF($B23="","",COUNTIFS(Calibración!$B$3:$B$152,$B23,Calibración!$Q$3:$Q$152,"VENCIDO"))
H24: =IF($B24="","",IF(COUNTIFS(Calibración!$B$3:$B$152,$B24,Calibración!$I$3:$I$152,"Sí")>0,"Sí","No")) | I24: =IF($B24="","",COUNTIFS(Calibración!$B$3:$B$152,$B24,Calibración!$Q$3:$Q$152,"VENCIDO"))
H25: =IF($B25="","",IF(COUNTIFS(Calibración!$B$3:$B$152,$B25,Calibración!$I$3:$I$152,"Sí")>0,"Sí","No")) | I25: =IF($B25="","",COUNTIFS(Calibración!$B$3:$B$152,$B25,Calibración!$Q$3:$Q$152,"VENCIDO"))
H26: =IF($B26="","",IF(COUNTIFS(Calibración!$B$3:$B$152,$B26,Calibración!$I$3:$I$152,"Sí")>0,"Sí","No")) | I26: =IF($B26="","",COUNTIFS(Calibración!$B$3:$B$152,$B26,Calibración!$Q$3:$Q$152,"VENCIDO"))
H27: =IF($B27="","",IF(COUNTIFS(Calibración!$B$3:$B$152,$B27,Calibración!$I$3:$I$152,"Sí")>0,"Sí","No")) | I27: =IF($B27="","",COUNTIFS(Calibración!$B$3:$B$152,$B27,Calibración!$Q$3:$Q$152,"VENCIDO"))
H28: =IF($B28="","",IF(COUNTIFS(Calibración!$B$3:$B$152,$B28,Calibración!$I$3:$I$152,"Sí")>0,"Sí","No")) | I28: =IF($B28="","",COUNTIFS(Calibración!$B$3:$B$152,$B28,Calibración!$Q$3:$Q$152,"VENCIDO"))
... H202: =IF($B202="","",IF(COUNTIFS(Calibración!$B$3:$B$152,$B202,Calibración!$I$3:$I$152,"Sí")>0,"Sí","No")) | I202: =IF($B202="","",COUNTIFS(Calibración!$B$3:$B$152,$B202,Calibración!$Q$3:$Q$152,"VENCIDO"))

Sheet Actividades
B1: CATÁLOGO DE ACTIVIDADES DE MANTENIMIENTO | D1: Código: COP15-F11 Revisión: 03 Fecha de emisión: 15/07/2026
A2: ID Act. | B2: Equipo | C2: Actividad | D2: Frecuencia | E2: Semana inicio (1-52) | F2: Responsable
A3: A-01 | B3: Dynamometer | C3: Limpieza (soplado) | D3: Mensual | E3: 2 | F3: Técnico
A4: A-02 | B4: HVAC | C4: Inspección general de filtros | D4: Trimestral | E4: 1 | F4: Técnico
A5: A-03 | B5: Clean Cham | C5: Reemplazo (componentes) | D5: Semestral | E5: 26 | F5: General

Sheet Plan Maestro
B1: PLAN MAESTRO DE MANTENIMIENTO | BD1: Código: COP15-F11 Revisión: 03 Fecha de emisión: 15/07/2026
A2: Año: | B2: 2026 | C2: ← única celda editable de esta hoja; la matriz se recalcula sin perder el historial
D3: =TEXT(DATE($B$2,1,1)+(1-1)*7,"[$-C0A]mmm") -> ene | E3: =TEXT(DATE($B$2,1,1)+(2-1)*7,"[$-C0A]mmm") -> ene | F3: =TEXT(DATE($B$2,1,1)+(3-1)*7,"[$-C0A]mmm") -> ene | G3: =TEXT(DATE($B$2,1,1)+(4-1)*7,"[$-C0A]mmm") -> ene | H3: =TEXT(DATE($B$2,1,1)+(5-1)*7,"[$-C0A]mmm") -> ene | I3: =TEXT(DATE($B$2,1,1)+(6-1)*7,"[$-C0A]mmm") -> feb | J3: =TEXT(DATE($B$2,1,1)+(7-1)*7,"[$-C0A]mmm") -> feb | K3: =TEXT(DATE($B$2,1,1)+(8-1)*7,"[$-C0A]mmm") -> feb | L3: =TEXT(DATE($B$2,1,1)+(9-1)*7,"[$-C0A]mmm") -> feb | M3: =TEXT(DATE($B$2,1,1)+(10-1)*7,"[$-C0A]mmm") -> mar | N3: =TEXT(DATE($B$2,1,1)+(11-1)*7,"[$-C0A]mmm") -> mar | O3: =TEXT(DATE($B$2,1,1)+(12-1)*7,"[$-C0A]mmm") -> mar | P3: =TEXT(DATE($B$2,1,1)+(13-1)*7,"[$-C0A]mmm") -> mar | Q3: =TEXT(DATE($B$2,1,1)+(14-1)*7,"[$-C0A]mmm") -> abr | R3: =TEXT(DATE($B$2,1,1)+(15-1)*7,"[$-C0A]mmm") -> abr | S3: =TEXT(DATE($B$2,1,1)+(16-1)*7,"[$-C0A]mmm") -> abr | T3: =TEXT(DATE($B$2,1,1)+(17-1)*7,"[$-C0A]mmm") -> abr | U3: =TEXT(DATE($B$2,1,1)+(18-1)*7,"[$-C0A]mmm") -> abr | V3: =TEXT(DATE($B$2,1,1)+(19-1)*7,"[$-C0A]mmm") -> may | W3: =TEXT(DATE($B$2,1,1)+(20-1)*7,"[$-C0A]mmm") -> may | X3: =TEXT(DATE($B$2,1,1)+(21-1)*7,"[$-C0A]mmm") -> may | Y3: =TEXT(DATE($B$2,1,1)+(22-1)*7,"[$-C0A]mmm") -> may | Z3: =TEXT(DATE($B$2,1,1)+(23-1)*7,"[$-C0A]mmm") -> jun | AA3: =TEXT(DATE($B$2,1,1)+(24-1)*7,"[$-C0A]mmm") -> jun | AB3: =TEXT(DATE($B$2,1,1)+(25-1)*7,"[$-C0A]mmm") -> jun | AC3: =TEXT(DATE($B$2,1,1)+(26-1)*7,"[$-C0A]mmm") -> jun | AD3: =TEXT(DATE($B$2,1,1)+(27-1)*7,"[$-C0A]mmm") -> jul | AE3: =TEXT(DATE($B$2,1,1)+(28-1)*7,"[$-C0A]mmm") -> jul | AF3: =TEXT(DATE($B$2,1,1)+(29-1)*7,"[$-C0A]mmm") -> jul | AG3: =TEXT(DATE($B$2,1,1)+(30-1)*7,"[$-C0A]mmm") -> jul | AH3: =TEXT(DATE($B$2,1,1)+(31-1)*7,"[$-C0A]mmm") -> jul | AI3: =TEXT(DATE($B$2,1,1)+(32-1)*7,"[$-C0A]mmm") -> ago | AJ3: =TEXT(DATE($B$2,1,1)+(33-1)*7,"[$-C0A]mmm") -> ago | AK3: =TEXT(DATE($B$2,1,1)+(34-1)*7,"[$-C0A]mmm") -> ago | AL3: =TEXT(DATE($B$2,1,1)+(35-1)*7,"[$-C0A]mmm") -> ago | AM3: =TEXT(DATE($B$2,1,1)+(36-1)*7,"[$-C0A]mmm") -> sep | AN3: =TEXT(DATE($B$2,1,1)+(37-1)*7,"[$-C0A]mmm") -> sep | AO3: =TEXT(DATE($B$2,1,1)+(38-1)*7,"[$-C0A]mmm") -> sep | AP3: =TEXT(DATE($B$2,1,1)+(39-1)*7,"[$-C0A]mmm") -> sep | AQ3: =TEXT(DATE($B$2,1,1)+(40-1)*7,"[$-C0A]mmm") -> oct | AR3: =TEXT(DATE($B$2,1,1)+(41-1)*7,"[$-C0A]mmm") -> oct | AS3: =TEXT(DATE($B$2,1,1)+(42-1)*7,"[$-C0A]mmm") -> oct | AT3: =TEXT(DATE($B$2,1,1)+(43-1)*7,"[$-C0A]mmm") -> oct | AU3: =TEXT(DATE($B$2,1,1)+(44-1)*7,"[$-C0A]mmm") -> oct | AV3: =TEXT(DATE($B$2,1,1)+(45-1)*7,"[$-C0A]mmm") -> nov | AW3: =TEXT(DATE($B$2,1,1)+(46-1)*7,"[$-C0A]mmm") -> nov | AX3: =TEXT(DATE($B$2,1,1)+(47-1)*7,"[$-C0A]mmm") -> nov | AY3: =TEXT(DATE($B$2,1,1)+(48-1)*7,"[$-C0A]mmm") -> nov | AZ3: =TEXT(DATE($B$2,1,1)+(49-1)*7,"[$-C0A]mmm") -> dic | BA3: =TEXT(DATE($B$2,1,1)+(50-1)*7,"[$-C0A]mmm") -> dic | BB3: =TEXT(DATE($B$2,1,1)+(51-1)*7,"[$-C0A]mmm") -> dic | BC3: =TEXT(DATE($B$2,1,1)+(52-1)*7,"[$-C0A]mmm") -> dic
A4: Equipo | B4: Actividad | C4: Plan/Real | D4: 1 | E4: 2 | F4: 3 | G4: 4 | H4: 5 | I4: 6 | J4: 7 | K4: 8 | L4: 9 | M4: 10 | N4: 11 | O4: 12 | P4: 13 | Q4: 14 | R4: 15 | S4: 16 | T4: 17 | U4: 18 | V4: 19 | W4: 20 | X4: 21 | Y4: 22 | Z4: 23 | AA4: 24 | AB4: 25 | AC4: 26 | AD4: 27 | AE4: 28 | AF4: 29 | AG4: 30 | AH4: 31 | AI4: 32 | AJ4: 33 | AK4: 34 | AL4: 35 | AM4: 36 | AN4: 37 | AO4: 38 | AP4: 39 | AQ4: 40 | AR4: 41 | AS4: 42 | AT4: 43 | AU4: 44 | AV4: 45 | AW4: 46 | AX4: 47 | AY4: 48 | AZ4: 49 | BA4: 50 | BB4: 51 | BC4: 52 | BD4: Plan | BE4: Real | BF4: % Cumpl.
A5: =IF(Actividades!$B3="","",Actividades!$B3) -> Dynamometer | B5: =IF(Actividades!$C3="","",Actividades!$C3) -> Limpieza (soplado) | C5: =IF($A5="","","Plan") -> Plan | D5: =IF($A5="","",IF(AND(N(Actividades!$E3)>0,D$4>=Actividades!$E3,MOD(D$4-Actividades!$E3,IFERROR(VLOOKUP(Actividades!$D3,Listas!$A$2:$B$8,2,0),52))=0),"P","")) | E5: =IF($A5="","",IF(AND(N(Actividades!$E3)>0,E$4>=Actividades!$E3,MOD(E$4-Actividades!$E3,IFERROR(VLOOKUP(Actividades!$D3,Listas!$A$2:$B$8,2,0),52))=0),"P","")) -> P | F5: =IF($A5="","",IF(AND(N(Actividades!$E3)>0,F$4>=Actividades!$E3,MOD(F$4-Actividades!$E3,IFERROR(VLOOKUP(Actividades!$D3,Listas!$A$2:$B$8,2,0),52))=0),"P","")) | G5: =IF($A5="","",IF(AND(N(Actividades!$E3)>0,G$4>=Actividades!$E3,MOD(G$4-Actividades!$E3,IFERROR(VLOOKUP(Actividades!$D3,Listas!$A$2:$B$8,2,0),52))=0),"P","")) | H5: =IF($A5="","",IF(AND(N(Actividades!$E3)>0,H$4>=Actividades!$E3,MOD(H$4-Actividades!$E3,IFERROR(VLOOKUP(Actividades!$D3,Listas!$A$2:$B$8,2,0),52))=0),"P","")) | I5: =IF($A5="","",IF(AND(N(Actividades!$E3)>0,I$4>=Actividades!$E3,MOD(I$4-Actividades!$E3,IFERROR(VLOOKUP(Actividades!$D3,Listas!$A$2:$B$8,2,0),52))=0),"P","")) -> P | J5: =IF($A5="","",IF(AND(N(Actividades!$E3)>0,J$4>=Actividades!$E3,MOD(J$4-Actividades!$E3,IFERROR(VLOOKUP(Actividades!$D3,Listas!$A$2:$B$8,2,0),52))=0),"P","")) | K5: =IF($A5="","",IF(AND(N(Actividades!$E3)>0,K$4>=Actividades!$E3,MOD(K$4-Actividades!$E3,IFERROR(VLOOKUP(Actividades!$D3,Listas!$A$2:$B$8,2,0),52))=0),"P","")) | ... BC5: =IF($A5="","",IF(AND(N(Actividades!$E3)>0,BC$4>=Actividades!$E3,MOD(BC$4-Actividades!$E3,IFERROR(VLOOKUP(Actividades!$D3,Listas!$A$2:$B$8,2,0),52))=0),"P","")) | BD5: =IF($A5="","",COUNTIF(D5:BC5,"P")) -> 13 | BE5: =IF($A5="","",SUMPRODUCT((D5:BC5="P")*(D6:BC6="✓"))) -> 1 | BF5: =IF($A5="","",IF(BD5=0,"",BE5/BD5)) -> 0.076923077
C6: =IF($A5="","","Real") -> Real | D6: =IF($A5="","",IF(COUNTIFS(Historial!$B$3:$B$502,$A5,Historial!$C$3:$C$502,$B5,Historial!$G$3:$G$502,D$4,Historial!$H$3:$H$502,$B$2)>0,"✓","")) | E6: =IF($A5="","",IF(COUNTIFS(Historial!$B$3:$B$502,$A5,Historial!$C$3:$C$502,$B5,Historial!$G$3:$G$502,E$4,Historial!$H$3:$H$502,$B$2)>0,"✓","")) -> ✓ | F6: =IF($A5="","",IF(COUNTIFS(Historial!$B$3:$B$502,$A5,Historial!$C$3:$C$502,$B5,Historial!$G$3:$G$502,F$4,Historial!$H$3:$H$502,$B$2)>0,"✓","")) | G6: =IF($A5="","",IF(COUNTIFS(Historial!$B$3:$B$502,$A5,Historial!$C$3:$C$502,$B5,Historial!$G$3:$G$502,G$4,Historial!$H$3:$H$502,$B$2)>0,"✓","")) | H6: =IF($A5="","",IF(COUNTIFS(Historial!$B$3:$B$502,$A5,Historial!$C$3:$C$502,$B5,Historial!$G$3:$G$502,H$4,Historial!$H$3:$H$502,$B$2)>0,"✓","")) | I6: =IF($A5="","",IF(COUNTIFS(Historial!$B$3:$B$502,$A5,Historial!$C$3:$C$502,$B5,Historial!$G$3:$G$502,I$4,Historial!$H$3:$H$502,$B$2)>0,"✓","")) | J6: =IF($A5="","",IF(COUNTIFS(Historial!$B$3:$B$502,$A5,Historial!$C$3:$C$502,$B5,Historial!$G$3:$G$502,J$4,Historial!$H$3:$H$502,$B$2)>0,"✓","")) | K6: =IF($A5="","",IF(COUNTIFS(Historial!$B$3:$B$502,$A5,Historial!$C$3:$C$502,$B5,Historial!$G$3:$G$502,K$4,Historial!$H$3:$H$502,$B$2)>0,"✓","")) | ... BC6: =IF($A5="","",IF(COUNTIFS(Historial!$B$3:$B$502,$A5,Historial!$C$3:$C$502,$B5,Historial!$G$3:$G$502,BC$4,Historial!$H$3:$H$502,$B$2)>0,"✓",""))
A7: =IF(Actividades!$B4="","",Actividades!$B4) -> HVAC | B7: =IF(Actividades!$C4="","",Actividades!$C4) -> Inspección general de filtros | C7: =IF($A7="","","Plan") -> Plan | D7: =IF($A7="","",IF(AND(N(Actividades!$E4)>0,D$4>=Actividades!$E4,MOD(D$4-Actividades!$E4,IFERROR(VLOOKUP(Actividades!$D4,Listas!$A$2:$B$8,2,0),52))=0),"P","")) -> P | E7: =IF($A7="","",IF(AND(N(Actividades!$E4)>0,E$4>=Actividades!$E4,MOD(E$4-Actividades!$E4,IFERROR(VLOOKUP(Actividades!$D4,Listas!$A$2:$B$8,2,0),52))=0),"P","")) | F7: =IF($A7="","",IF(AND(N(Actividades!$E4)>0,F$4>=Actividades!$E4,MOD(F$4-Actividades!$E4,IFERROR(VLOOKUP(Actividades!$D4,Listas!$A$2:$B$8,2,0),52))=0),"P","")) | G7: =IF($A7="","",IF(AND(N(Actividades!$E4)>0,G$4>=Actividades!$E4,MOD(G$4-Actividades!$E4,IFERROR(VLOOKUP(Actividades!$D4,Listas!$A$2:$B$8,2,0),52))=0),"P","")) | H7: =IF($A7="","",IF(AND(N(Actividades!$E4)>0,H$4>=Actividades!$E4,MOD(H$4-Actividades!$E4,IFERROR(VLOOKUP(Actividades!$D4,Listas!$A$2:$B$8,2,0),52))=0),"P","")) | I7: =IF($A7="","",IF(AND(N(Actividades!$E4)>0,I$4>=Actividades!$E4,MOD(I$4-Actividades!$E4,IFERROR(VLOOKUP(Actividades!$D4,Listas!$A$2:$B$8,2,0),52))=0),"P","")) | J7: =IF($A7="","",IF(AND(N(Actividades!$E4)>0,J$4>=Actividades!$E4,MOD(J$4-Actividades!$E4,IFERROR(VLOOKUP(Actividades!$D4,Listas!$A$2:$B$8,2,0),52))=0),"P","")) | K7: =IF($A7="","",IF(AND(N(Actividades!$E4)>0,K$4>=Actividades!$E4,MOD(K$4-Actividades!$E4,IFERROR(VLOOKUP(Actividades!$D4,Listas!$A$2:$B$8,2,0),52))=0),"P","")) | ... BC7: =IF($A7="","",IF(AND(N(Actividades!$E4)>0,BC$4>=Actividades!$E4,MOD(BC$4-Actividades!$E4,IFERROR(VLOOKUP(Actividades!$D4,Listas!$A$2:$B$8,2,0),52))=0),"P","")) | BD7: =IF($A7="","",COUNTIF(D7:BC7,"P")) -> 4 | BE7: =IF($A7="","",SUMPRODUCT((D7:BC7="P")*(D8:BC8="✓"))) -> 0 | BF7: =IF($A7="","",IF(BD7=0,"",BE7/BD7)) -> 0
C8: =IF($A7="","","Real") -> Real | D8: =IF($A7="","",IF(COUNTIFS(Historial!$B$3:$B$502,$A7,Historial!$C$3:$C$502,$B7,Historial!$G$3:$G$502,D$4,Historial!$H$3:$H$502,$B$2)>0,"✓","")) | E8: =IF($A7="","",IF(COUNTIFS(Historial!$B$3:$B$502,$A7,Historial!$C$3:$C$502,$B7,Historial!$G$3:$G$502,E$4,Historial!$H$3:$H$502,$B$2)>0,"✓","")) | F8: =IF($A7="","",IF(COUNTIFS(Historial!$B$3:$B$502,$A7,Historial!$C$3:$C$502,$B7,Historial!$G$3:$G$502,F$4,Historial!$H$3:$H$502,$B$2)>0,"✓","")) | G8: =IF($A7="","",IF(COUNTIFS(Historial!$B$3:$B$502,$A7,Historial!$C$3:$C$502,$B7,Historial!$G$3:$G$502,G$4,Historial!$H$3:$H$502,$B$2)>0,"✓","")) | H8: =IF($A7="","",IF(COUNTIFS(Historial!$B$3:$B$502,$A7,Historial!$C$3:$C$502,$B7,Historial!$G$3:$G$502,H$4,Historial!$H$3:$H$502,$B$2)>0,"✓","")) | I8: =IF($A7="","",IF(COUNTIFS(Historial!$B$3:$B$502,$A7,Historial!$C$3:$C$502,$B7,Historial!$G$3:$G$502,I$4,Historial!$H$3:$H$502,$B$2)>0,"✓","")) | J8: =IF($A7="","",IF(COUNTIFS(Historial!$B$3:$B$502,$A7,Historial!$C$3:$C$502,$B7,Historial!$G$3:$G$502,J$4,Historial!$H$3:$H$502,$B$2)>0,"✓","")) | K8: =IF($A7="","",IF(COUNTIFS(Historial!$B$3:$B$502,$A7,Historial!$C$3:$C$502,$B7,Historial!$G$3:$G$502,K$4,Historial!$H$3:$H$502,$B$2)>0,"✓","")) | ... BC8: =IF($A7="","",IF(COUNTIFS(Historial!$B$3:$B$502,$A7,Historial!$C$3:$C$502,$B7,Historial!$G$3:$G$502,BC$4,Historial!$H$3:$H$502,$B$2)>0,"✓",""))
A9: =IF(Actividades!$B5="","",Actividades!$B5) -> Clean Cham | B9: =IF(Actividades!$C5="","",Actividades!$C5) -> Reemplazo (componentes) | C9: =IF($A9="","","Plan") -> Plan | D9: =IF($A9="","",IF(AND(N(Actividades!$E5)>0,D$4>=Actividades!$E5,MOD(D$4-Actividades!$E5,IFERROR(VLOOKUP(Actividades!$D5,Listas!$A$2:$B$8,2,0),52))=0),"P","")) | E9: =IF($A9="","",IF(AND(N(Actividades!$E5)>0,E$4>=Actividades!$E5,MOD(E$4-Actividades!$E5,IFERROR(VLOOKUP(Actividades!$D5,Listas!$A$2:$B$8,2,0),52))=0),"P","")) | F9: =IF($A9="","",IF(AND(N(Actividades!$E5)>0,F$4>=Actividades!$E5,MOD(F$4-Actividades!$E5,IFERROR(VLOOKUP(Actividades!$D5,Listas!$A$2:$B$8,2,0),52))=0),"P","")) | G9: =IF($A9="","",IF(AND(N(Actividades!$E5)>0,G$4>=Actividades!$E5,MOD(G$4-Actividades!$E5,IFERROR(VLOOKUP(Actividades!$D5,Listas!$A$2:$B$8,2,0),52))=0),"P","")) | H9: =IF($A9="","",IF(AND(N(Actividades!$E5)>0,H$4>=Actividades!$E5,MOD(H$4-Actividades!$E5,IFERROR(VLOOKUP(Actividades!$D5,Listas!$A$2:$B$8,2,0),52))=0),"P","")) | I9: =IF($A9="","",IF(AND(N(Actividades!$E5)>0,I$4>=Actividades!$E5,MOD(I$4-Actividades!$E5,IFERROR(VLOOKUP(Actividades!$D5,Listas!$A$2:$B$8,2,0),52))=0),"P","")) | J9: =IF($A9="","",IF(AND(N(Actividades!$E5)>0,J$4>=Actividades!$E5,MOD(J$4-Actividades!$E5,IFERROR(VLOOKUP(Actividades!$D5,Listas!$A$2:$B$8,2,0),52))=0),"P","")) | K9: =IF($A9="","",IF(AND(N(Actividades!$E5)>0,K$4>=Actividades!$E5,MOD(K$4-Actividades!$E5,IFERROR(VLOOKUP(Actividades!$D5,Listas!$A$2:$B$8,2,0),52))=0),"P","")) | ... BC9: =IF($A9="","",IF(AND(N(Actividades!$E5)>0,BC$4>=Actividades!$E5,MOD(BC$4-Actividades!$E5,IFERROR(VLOOKUP(Actividades!$D5,Listas!$A$2:$B$8,2,0),52))=0),"P","")) -> P | BD9: =IF($A9="","",COUNTIF(D9:BC9,"P")) -> 2 | BE9: =IF($A9="","",SUMPRODUCT((D9:BC9="P")*(D10:BC10="✓"))) -> 0 | BF9: =IF($A9="","",IF(BD9=0,"",BE9/BD9)) -> 0
C10: =IF($A9="","","Real") -> Real | D10: =IF($A9="","",IF(COUNTIFS(Historial!$B$3:$B$502,$A9,Historial!$C$3:$C$502,$B9,Historial!$G$3:$G$502,D$4,Historial!$H$3:$H$502,$B$2)>0,"✓","")) | E10: =IF($A9="","",IF(COUNTIFS(Historial!$B$3:$B$502,$A9,Historial!$C$3:$C$502,$B9,Historial!$G$3:$G$502,E$4,Historial!$H$3:$H$502,$B$2)>0,"✓","")) | F10: =IF($A9="","",IF(COUNTIFS(Historial!$B$3:$B$502,$A9,Historial!$C$3:$C$502,$B9,Historial!$G$3:$G$502,F$4,Historial!$H$3:$H$502,$B$2)>0,"✓","")) | G10: =IF($A9="","",IF(COUNTIFS(Historial!$B$3:$B$502,$A9,Historial!$C$3:$C$502,$B9,Historial!$G$3:$G$502,G$4,Historial!$H$3:$H$502,$B$2)>0,"✓","")) | H10: =IF($A9="","",IF(COUNTIFS(Historial!$B$3:$B$502,$A9,Historial!$C$3:$C$502,$B9,Historial!$G$3:$G$502,H$4,Historial!$H$3:$H$502,$B$2)>0,"✓","")) | I10: =IF($A9="","",IF(COUNTIFS(Historial!$B$3:$B$502,$A9,Historial!$C$3:$C$502,$B9,Historial!$G$3:$G$502,I$4,Historial!$H$3:$H$502,$B$2)>0,"✓","")) | J10: =IF($A9="","",IF(COUNTIFS(Historial!$B$3:$B$502,$A9,Historial!$C$3:$C$502,$B9,Historial!$G$3:$G$502,J$4,Historial!$H$3:$H$502,$B$2)>0,"✓","")) | K10: =IF($A9="","",IF(COUNTIFS(Historial!$B$3:$B$502,$A9,Historial!$C$3:$C$502,$B9,Historial!$G$3:$G$502,K$4,Historial!$H$3:$H$502,$B$2)>0,"✓","")) | ... BC10: =IF($A9="","",IF(COUNTIFS(Historial!$B$3:$B$502,$A9,Historial!$C$3:$C$502,$B9,Historial!$G$3:$G$502,BC$4,Historial!$H$3:$H$502,$B$2)>0,"✓",""))
A11: =IF(Actividades!$B6="","",Actividades!$B6) | B11: =IF(Actividades!$C6="","",Actividades!$C6) | C11: =IF($A11="","","Plan") | D11: =IF($A11="","",IF(AND(N(Actividades!$E6)>0,D$4>=Actividades!$E6,MOD(D$4-Actividades!$E6,IFERROR(VLOOKUP(Actividades!$D6,Listas!$A$2:$B$8,2,0),52))=0),"P","")) | E11: =IF($A11="","",IF(AND(N(Actividades!$E6)>0,E$4>=Actividades!$E6,MOD(E$4-Actividades!$E6,IFERROR(VLOOKUP(Actividades!$D6,Listas!$A$2:$B$8,2,0),52))=0),"P","")) | F11: =IF($A11="","",IF(AND(N(Actividades!$E6)>0,F$4>=Actividades!$E6,MOD(F$4-Actividades!$E6,IFERROR(VLOOKUP(Actividades!$D6,Listas!$A$2:$B$8,2,0),52))=0),"P","")) | G11: =IF($A11="","",IF(AND(N(Actividades!$E6)>0,G$4>=Actividades!$E6,MOD(G$4-Actividades!$E6,IFERROR(VLOOKUP(Actividades!$D6,Listas!$A$2:$B$8,2,0),52))=0),"P","")) | H11: =IF($A11="","",IF(AND(N(Actividades!$E6)>0,H$4>=Actividades!$E6,MOD(H$4-Actividades!$E6,IFERROR(VLOOKUP(Actividades!$D6,Listas!$A$2:$B$8,2,0),52))=0),"P","")) | I11: =IF($A11="","",IF(AND(N(Actividades!$E6)>0,I$4>=Actividades!$E6,MOD(I$4-Actividades!$E6,IFERROR(VLOOKUP(Actividades!$D6,Listas!$A$2:$B$8,2,0),52))=0),"P","")) | J11: =IF($A11="","",IF(AND(N(Actividades!$E6)>0,J$4>=Actividades!$E6,MOD(J$4-Actividades!$E6,IFERROR(VLOOKUP(Actividades!$D6,Listas!$A$2:$B$8,2,0),52))=0),"P","")) | K11: =IF($A11="","",IF(AND(N(Actividades!$E6)>0,K$4>=Actividades!$E6,MOD(K$4-Actividades!$E6,IFERROR(VLOOKUP(Actividades!$D6,Listas!$A$2:$B$8,2,0),52))=0),"P","")) | ... BC11: =IF($A11="","",IF(AND(N(Actividades!$E6)>0,BC$4>=Actividades!$E6,MOD(BC$4-Actividades!$E6,IFERROR(VLOOKUP(Actividades!$D6,Listas!$A$2:$B$8,2,0),52))=0),"P","")) | BD11: =IF($A11="","",COUNTIF(D11:BC11,"P")) | BE11: =IF($A11="","",SUMPRODUCT((D11:BC11="P")*(D12:BC12="✓"))) | BF11: =IF($A11="","",IF(BD11=0,"",BE11/BD11))
C12: =IF($A11="","","Real") | D12: =IF($A11="","",IF(COUNTIFS(Historial!$B$3:$B$502,$A11,Historial!$C$3:$C$502,$B11,Historial!$G$3:$G$502,D$4,Historial!$H$3:$H$502,$B$2)>0,"✓","")) | E12: =IF($A11="","",IF(COUNTIFS(Historial!$B$3:$B$502,$A11,Historial!$C$3:$C$502,$B11,Historial!$G$3:$G$502,E$4,Historial!$H$3:$H$502,$B$2)>0,"✓","")) | F12: =IF($A11="","",IF(COUNTIFS(Historial!$B$3:$B$502,$A11,Historial!$C$3:$C$502,$B11,Historial!$G$3:$G$502,F$4,Historial!$H$3:$H$502,$B$2)>0,"✓","")) | G12: =IF($A11="","",IF(COUNTIFS(Historial!$B$3:$B$502,$A11,Historial!$C$3:$C$502,$B11,Historial!$G$3:$G$502,G$4,Historial!$H$3:$H$502,$B$2)>0,"✓","")) | H12: =IF($A11="","",IF(COUNTIFS(Historial!$B$3:$B$502,$A11,Historial!$C$3:$C$502,$B11,Historial!$G$3:$G$502,H$4,Historial!$H$3:$H$502,$B$2)>0,"✓","")) | I12: =IF($A11="","",IF(COUNTIFS(Historial!$B$3:$B$502,$A11,Historial!$C$3:$C$502,$B11,Historial!$G$3:$G$502,I$4,Historial!$H$3:$H$502,$B$2)>0,"✓","")) | J12: =IF($A11="","",IF(COUNTIFS(Historial!$B$3:$B$502,$A11,Historial!$C$3:$C$502,$B11,Historial!$G$3:$G$502,J$4,Historial!$H$3:$H$502,$B$2)>0,"✓","")) | K12: =IF($A11="","",IF(COUNTIFS(Historial!$B$3:$B$502,$A11,Historial!$C$3:$C$502,$B11,Historial!$G$3:$G$502,K$4,Historial!$H$3:$H$502,$B$2)>0,"✓","")) | ... BC12: =IF($A11="","",IF(COUNTIFS(Historial!$B$3:$B$502,$A11,Historial!$C$3:$C$502,$B11,Historial!$G$3:$G$502,BC$4,Historial!$H$3:$H$502,$B$2)>0,"✓",""))
A13: =IF(Actividades!$B7="","",Actividades!$B7) | B13: =IF(Actividades!$C7="","",Actividades!$C7) | C13: =IF($A13="","","Plan") | D13: =IF($A13="","",IF(AND(N(Actividades!$E7)>0,D$4>=Actividades!$E7,MOD(D$4-Actividades!$E7,IFERROR(VLOOKUP(Actividades!$D7,Listas!$A$2:$B$8,2,0),52))=0),"P","")) | E13: =IF($A13="","",IF(AND(N(Actividades!$E7)>0,E$4>=Actividades!$E7,MOD(E$4-Actividades!$E7,IFERROR(VLOOKUP(Actividades!$D7,Listas!$A$2:$B$8,2,0),52))=0),"P","")) | F13: =IF($A13="","",IF(AND(N(Actividades!$E7)>0,F$4>=Actividades!$E7,MOD(F$4-Actividades!$E7,IFERROR(VLOOKUP(Actividades!$D7,Listas!$A$2:$B$8,2,0),52))=0),"P","")) | G13: =IF($A13="","",IF(AND(N(Actividades!$E7)>0,G$4>=Actividades!$E7,MOD(G$4-Actividades!$E7,IFERROR(VLOOKUP(Actividades!$D7,Listas!$A$2:$B$8,2,0),52))=0),"P","")) | H13: =IF($A13="","",IF(AND(N(Actividades!$E7)>0,H$4>=Actividades!$E7,MOD(H$4-Actividades!$E7,IFERROR(VLOOKUP(Actividades!$D7,Listas!$A$2:$B$8,2,0),52))=0),"P","")) | I13: =IF($A13="","",IF(AND(N(Actividades!$E7)>0,I$4>=Actividades!$E7,MOD(I$4-Actividades!$E7,IFERROR(VLOOKUP(Actividades!$D7,Listas!$A$2:$B$8,2,0),52))=0),"P","")) | J13: =IF($A13="","",IF(AND(N(Actividades!$E7)>0,J$4>=Actividades!$E7,MOD(J$4-Actividades!$E7,IFERROR(VLOOKUP(Actividades!$D7,Listas!$A$2:$B$8,2,0),52))=0),"P","")) | K13: =IF($A13="","",IF(AND(N(Actividades!$E7)>0,K$4>=Actividades!$E7,MOD(K$4-Actividades!$E7,IFERROR(VLOOKUP(Actividades!$D7,Listas!$A$2:$B$8,2,0),52))=0),"P","")) | ... BC13: =IF($A13="","",IF(AND(N(Actividades!$E7)>0,BC$4>=Actividades!$E7,MOD(BC$4-Actividades!$E7,IFERROR(VLOOKUP(Actividades!$D7,Listas!$A$2:$B$8,2,0),52))=0),"P","")) | BD13: =IF($A13="","",COUNTIF(D13:BC13,"P")) | BE13: =IF($A13="","",SUMPRODUCT((D13:BC13="P")*(D14:BC14="✓"))) | BF13: =IF($A13="","",IF(BD13=0,"",BE13/BD13))
C14: =IF($A13="","","Real") | D14: =IF($A13="","",IF(COUNTIFS(Historial!$B$3:$B$502,$A13,Historial!$C$3:$C$502,$B13,Historial!$G$3:$G$502,D$4,Historial!$H$3:$H$502,$B$2)>0,"✓","")) | E14: =IF($A13="","",IF(COUNTIFS(Historial!$B$3:$B$502,$A13,Historial!$C$3:$C$502,$B13,Historial!$G$3:$G$502,E$4,Historial!$H$3:$H$502,$B$2)>0,"✓","")) | F14: =IF($A13="","",IF(COUNTIFS(Historial!$B$3:$B$502,$A13,Historial!$C$3:$C$502,$B13,Historial!$G$3:$G$502,F$4,Historial!$H$3:$H$502,$B$2)>0,"✓","")) | G14: =IF($A13="","",IF(COUNTIFS(Historial!$B$3:$B$502,$A13,Historial!$C$3:$C$502,$B13,Historial!$G$3:$G$502,G$4,Historial!$H$3:$H$502,$B$2)>0,"✓","")) | H14: =IF($A13="","",IF(COUNTIFS(Historial!$B$3:$B$502,$A13,Historial!$C$3:$C$502,$B13,Historial!$G$3:$G$502,H$4,Historial!$H$3:$H$502,$B$2)>0,"✓","")) | I14: =IF($A13="","",IF(COUNTIFS(Historial!$B$3:$B$502,$A13,Historial!$C$3:$C$502,$B13,Historial!$G$3:$G$502,I$4,Historial!$H$3:$H$502,$B$2)>0,"✓","")) | J14: =IF($A13="","",IF(COUNTIFS(Historial!$B$3:$B$502,$A13,Historial!$C$3:$C$502,$B13,Historial!$G$3:$G$502,J$4,Historial!$H$3:$H$502,$B$2)>0,"✓","")) | K14: =IF($A13="","",IF(COUNTIFS(Historial!$B$3:$B$502,$A13,Historial!$C$3:$C$502,$B13,Historial!$G$3:$G$502,K$4,Historial!$H$3:$H$502,$B$2)>0,"✓","")) | ... BC14: =IF($A13="","",IF(COUNTIFS(Historial!$B$3:$B$502,$A13,Historial!$C$3:$C$502,$B13,Historial!$G$3:$G$502,BC$4,Historial!$H$3:$H$502,$B$2)>0,"✓",""))
A15: =IF(Actividades!$B8="","",Actividades!$B8) | B15: =IF(Actividades!$C8="","",Actividades!$C8) | C15: =IF($A15="","","Plan") | D15: =IF($A15="","",IF(AND(N(Actividades!$E8)>0,D$4>=Actividades!$E8,MOD(D$4-Actividades!$E8,IFERROR(VLOOKUP(Actividades!$D8,Listas!$A$2:$B$8,2,0),52))=0),"P","")) | E15: =IF($A15="","",IF(AND(N(Actividades!$E8)>0,E$4>=Actividades!$E8,MOD(E$4-Actividades!$E8,IFERROR(VLOOKUP(Actividades!$D8,Listas!$A$2:$B$8,2,0),52))=0),"P","")) | F15: =IF($A15="","",IF(AND(N(Actividades!$E8)>0,F$4>=Actividades!$E8,MOD(F$4-Actividades!$E8,IFERROR(VLOOKUP(Actividades!$D8,Listas!$A$2:$B$8,2,0),52))=0),"P","")) | G15: =IF($A15="","",IF(AND(N(Actividades!$E8)>0,G$4>=Actividades!$E8,MOD(G$4-Actividades!$E8,IFERROR(VLOOKUP(Actividades!$D8,Listas!$A$2:$B$8,2,0),52))=0),"P","")) | H15: =IF($A15="","",IF(AND(N(Actividades!$E8)>0,H$4>=Actividades!$E8,MOD(H$4-Actividades!$E8,IFERROR(VLOOKUP(Actividades!$D8,Listas!$A$2:$B$8,2,0),52))=0),"P","")) | I15: =IF($A15="","",IF(AND(N(Actividades!$E8)>0,I$4>=Actividades!$E8,MOD(I$4-Actividades!$E8,IFERROR(VLOOKUP(Actividades!$D8,Listas!$A$2:$B$8,2,0),52))=0),"P","")) | J15: =IF($A15="","",IF(AND(N(Actividades!$E8)>0,J$4>=Actividades!$E8,MOD(J$4-Actividades!$E8,IFERROR(VLOOKUP(Actividades!$D8,Listas!$A$2:$B$8,2,0),52))=0),"P","")) | K15: =IF($A15="","",IF(AND(N(Actividades!$E8)>0,K$4>=Actividades!$E8,MOD(K$4-Actividades!$E8,IFERROR(VLOOKUP(Actividades!$D8,Listas!$A$2:$B$8,2,0),52))=0),"P","")) | ... BC15: =IF($A15="","",IF(AND(N(Actividades!$E8)>0,BC$4>=Actividades!$E8,MOD(BC$4-Actividades!$E8,IFERROR(VLOOKUP(Actividades!$D8,Listas!$A$2:$B$8,2,0),52))=0),"P","")) | BD15: =IF($A15="","",COUNTIF(D15:BC15,"P")) | BE15: =IF($A15="","",SUMPRODUCT((D15:BC15="P")*(D16:BC16="✓"))) | BF15: =IF($A15="","",IF(BD15=0,"",BE15/BD15))
C16: =IF($A15="","","Real") | D16: =IF($A15="","",IF(COUNTIFS(Historial!$B$3:$B$502,$A15,Historial!$C$3:$C$502,$B15,Historial!$G$3:$G$502,D$4,Historial!$H$3:$H$502,$B$2)>0,"✓","")) | E16: =IF($A15="","",IF(COUNTIFS(Historial!$B$3:$B$502,$A15,Historial!$C$3:$C$502,$B15,Historial!$G$3:$G$502,E$4,Historial!$H$3:$H$502,$B$2)>0,"✓","")) | F16: =IF($A15="","",IF(COUNTIFS(Historial!$B$3:$B$502,$A15,Historial!$C$3:$C$502,$B15,Historial!$G$3:$G$502,F$4,Historial!$H$3:$H$502,$B$2)>0,"✓","")) | G16: =IF($A15="","",IF(COUNTIFS(Historial!$B$3:$B$502,$A15,Historial!$C$3:$C$502,$B15,Historial!$G$3:$G$502,G$4,Historial!$H$3:$H$502,$B$2)>0,"✓","")) | H16: =IF($A15="","",IF(COUNTIFS(Historial!$B$3:$B$502,$A15,Historial!$C$3:$C$502,$B15,Historial!$G$3:$G$502,H$4,Historial!$H$3:$H$502,$B$2)>0,"✓","")) | I16: =IF($A15="","",IF(COUNTIFS(Historial!$B$3:$B$502,$A15,Historial!$C$3:$C$502,$B15,Historial!$G$3:$G$502,I$4,Historial!$H$3:$H$502,$B$2)>0,"✓","")) | J16: =IF($A15="","",IF(COUNTIFS(Historial!$B$3:$B$502,$A15,Historial!$C$3:$C$502,$B15,Historial!$G$3:$G$502,J$4,Historial!$H$3:$H$502,$B$2)>0,"✓","")) | K16: =IF($A15="","",IF(COUNTIFS(Historial!$B$3:$B$502,$A15,Historial!$C$3:$C$502,$B15,Historial!$G$3:$G$502,K$4,Historial!$H$3:$H$502,$B$2)>0,"✓","")) | ... BC16: =IF($A15="","",IF(COUNTIFS(Historial!$B$3:$B$502,$A15,Historial!$C$3:$C$502,$B15,Historial!$G$3:$G$502,BC$4,Historial!$H$3:$H$502,$B$2)>0,"✓",""))
A17: =IF(Actividades!$B9="","",Actividades!$B9) | B17: =IF(Actividades!$C9="","",Actividades!$C9) | C17: =IF($A17="","","Plan") | D17: =IF($A17="","",IF(AND(N(Actividades!$E9)>0,D$4>=Actividades!$E9,MOD(D$4-Actividades!$E9,IFERROR(VLOOKUP(Actividades!$D9,Listas!$A$2:$B$8,2,0),52))=0),"P","")) | E17: =IF($A17="","",IF(AND(N(Actividades!$E9)>0,E$4>=Actividades!$E9,MOD(E$4-Actividades!$E9,IFERROR(VLOOKUP(Actividades!$D9,Listas!$A$2:$B$8,2,0),52))=0),"P","")) | F17: =IF($A17="","",IF(AND(N(Actividades!$E9)>0,F$4>=Actividades!$E9,MOD(F$4-Actividades!$E9,IFERROR(VLOOKUP(Actividades!$D9,Listas!$A$2:$B$8,2,0),52))=0),"P","")) | G17: =IF($A17="","",IF(AND(N(Actividades!$E9)>0,G$4>=Actividades!$E9,MOD(G$4-Actividades!$E9,IFERROR(VLOOKUP(Actividades!$D9,Listas!$A$2:$B$8,2,0),52))=0),"P","")) | H17: =IF($A17="","",IF(AND(N(Actividades!$E9)>0,H$4>=Actividades!$E9,MOD(H$4-Actividades!$E9,IFERROR(VLOOKUP(Actividades!$D9,Listas!$A$2:$B$8,2,0),52))=0),"P","")) | I17: =IF($A17="","",IF(AND(N(Actividades!$E9)>0,I$4>=Actividades!$E9,MOD(I$4-Actividades!$E9,IFERROR(VLOOKUP(Actividades!$D9,Listas!$A$2:$B$8,2,0),52))=0),"P","")) | J17: =IF($A17="","",IF(AND(N(Actividades!$E9)>0,J$4>=Actividades!$E9,MOD(J$4-Actividades!$E9,IFERROR(VLOOKUP(Actividades!$D9,Listas!$A$2:$B$8,2,0),52))=0),"P","")) | K17: =IF($A17="","",IF(AND(N(Actividades!$E9)>0,K$4>=Actividades!$E9,MOD(K$4-Actividades!$E9,IFERROR(VLOOKUP(Actividades!$D9,Listas!$A$2:$B$8,2,0),52))=0),"P","")) | ... BC17: =IF($A17="","",IF(AND(N(Actividades!$E9)>0,BC$4>=Actividades!$E9,MOD(BC$4-Actividades!$E9,IFERROR(VLOOKUP(Actividades!$D9,Listas!$A$2:$B$8,2,0),52))=0),"P","")) | BD17: =IF($A17="","",COUNTIF(D17:BC17,"P")) | BE17: =IF($A17="","",SUMPRODUCT((D17:BC17="P")*(D18:BC18="✓"))) | BF17: =IF($A17="","",IF(BD17=0,"",BE17/BD17))
C18: =IF($A17="","","Real") | D18: =IF($A17="","",IF(COUNTIFS(Historial!$B$3:$B$502,$A17,Historial!$C$3:$C$502,$B17,Historial!$G$3:$G$502,D$4,Historial!$H$3:$H$502,$B$2)>0,"✓","")) | E18: =IF($A17="","",IF(COUNTIFS(Historial!$B$3:$B$502,$A17,Historial!$C$3:$C$502,$B17,Historial!$G$3:$G$502,E$4,Historial!$H$3:$H$502,$B$2)>0,"✓","")) | F18: =IF($A17="","",IF(COUNTIFS(Historial!$B$3:$B$502,$A17,Historial!$C$3:$C$502,$B17,Historial!$G$3:$G$502,F$4,Historial!$H$3:$H$502,$B$2)>0,"✓","")) | G18: =IF($A17="","",IF(COUNTIFS(Historial!$B$3:$B$502,$A17,Historial!$C$3:$C$502,$B17,Historial!$G$3:$G$502,G$4,Historial!$H$3:$H$502,$B$2)>0,"✓","")) | H18: =IF($A17="","",IF(COUNTIFS(Historial!$B$3:$B$502,$A17,Historial!$C$3:$C$502,$B17,Historial!$G$3:$G$502,H$4,Historial!$H$3:$H$502,$B$2)>0,"✓","")) | I18: =IF($A17="","",IF(COUNTIFS(Historial!$B$3:$B$502,$A17,Historial!$C$3:$C$502,$B17,Historial!$G$3:$G$502,I$4,Historial!$H$3:$H$502,$B$2)>0,"✓","")) | J18: =IF($A17="","",IF(COUNTIFS(Historial!$B$3:$B$502,$A17,Historial!$C$3:$C$502,$B17,Historial!$G$3:$G$502,J$4,Historial!$H$3:$H$502,$B$2)>0,"✓","")) | K18: =IF($A17="","",IF(COUNTIFS(Historial!$B$3:$B$502,$A17,Historial!$C$3:$C$502,$B17,Historial!$G$3:$G$502,K$4,Historial!$H$3:$H$502,$B$2)>0,"✓","")) | ... BC18: =IF($A17="","",IF(COUNTIFS(Historial!$B$3:$B$502,$A17,Historial!$C$3:$C$502,$B17,Historial!$G$3:$G$502,BC$4,Historial!$H$3:$H$502,$B$2)>0,"✓",""))
A19: =IF(Actividades!$B10="","",Actividades!$B10) | B19: =IF(Actividades!$C10="","",Actividades!$C10) | C19: =IF($A19="","","Plan") | D19: =IF($A19="","",IF(AND(N(Actividades!$E10)>0,D$4>=Actividades!$E10,MOD(D$4-Actividades!$E10,IFERROR(VLOOKUP(Actividades!$D10,Listas!$A$2:$B$8,2,0),52))=0),"P","")) | E19: =IF($A19="","",IF(AND(N(Actividades!$E10)>0,E$4>=Actividades!$E10,MOD(E$4-Actividades!$E10,IFERROR(VLOOKUP(Actividades!$D10,Listas!$A$2:$B$8,2,0),52))=0),"P","")) | F19: =IF($A19="","",IF(AND(N(Actividades!$E10)>0,F$4>=Actividades!$E10,MOD(F$4-Actividades!$E10,IFERROR(VLOOKUP(Actividades!$D10,Listas!$A$2:$B$8,2,0),52))=0),"P","")) | G19: =IF($A19="","",IF(AND(N(Actividades!$E10)>0,G$4>=Actividades!$E10,MOD(G$4-Actividades!$E10,IFERROR(VLOOKUP(Actividades!$D10,Listas!$A$2:$B$8,2,0),52))=0),"P","")) | H19: =IF($A19="","",IF(AND(N(Actividades!$E10)>0,H$4>=Actividades!$E10,MOD(H$4-Actividades!$E10,IFERROR(VLOOKUP(Actividades!$D10,Listas!$A$2:$B$8,2,0),52))=0),"P","")) | I19: =IF($A19="","",IF(AND(N(Actividades!$E10)>0,I$4>=Actividades!$E10,MOD(I$4-Actividades!$E10,IFERROR(VLOOKUP(Actividades!$D10,Listas!$A$2:$B$8,2,0),52))=0),"P","")) | J19: =IF($A19="","",IF(AND(N(Actividades!$E10)>0,J$4>=Actividades!$E10,MOD(J$4-Actividades!$E10,IFERROR(VLOOKUP(Actividades!$D10,Listas!$A$2:$B$8,2,0),52))=0),"P","")) | K19: =IF($A19="","",IF(AND(N(Actividades!$E10)>0,K$4>=Actividades!$E10,MOD(K$4-Actividades!$E10,IFERROR(VLOOKUP(Actividades!$D10,Listas!$A$2:$B$8,2,0),52))=0),"P","")) | ... BC19: =IF($A19="","",IF(AND(N(Actividades!$E10)>0,BC$4>=Actividades!$E10,MOD(BC$4-Actividades!$E10,IFERROR(VLOOKUP(Actividades!$D10,Listas!$A$2:$B$8,2,0),52))=0),"P","")) | BD19: =IF($A19="","",COUNTIF(D19:BC19,"P")) | BE19: =IF($A19="","",SUMPRODUCT((D19:BC19="P")*(D20:BC20="✓"))) | BF19: =IF($A19="","",IF(BD19=0,"",BE19/BD19))
C20: =IF($A19="","","Real") | D20: =IF($A19="","",IF(COUNTIFS(Historial!$B$3:$B$502,$A19,Historial!$C$3:$C$502,$B19,Historial!$G$3:$G$502,D$4,Historial!$H$3:$H$502,$B$2)>0,"✓","")) | E20: =IF($A19="","",IF(COUNTIFS(Historial!$B$3:$B$502,$A19,Historial!$C$3:$C$502,$B19,Historial!$G$3:$G$502,E$4,Historial!$H$3:$H$502,$B$2)>0,"✓","")) | F20: =IF($A19="","",IF(COUNTIFS(Historial!$B$3:$B$502,$A19,Historial!$C$3:$C$502,$B19,Historial!$G$3:$G$502,F$4,Historial!$H$3:$H$502,$B$2)>0,"✓","")) | G20: =IF($A19="","",IF(COUNTIFS(Historial!$B$3:$B$502,$A19,Historial!$C$3:$C$502,$B19,Historial!$G$3:$G$502,G$4,Historial!$H$3:$H$502,$B$2)>0,"✓","")) | H20: =IF($A19="","",IF(COUNTIFS(Historial!$B$3:$B$502,$A19,Historial!$C$3:$C$502,$B19,Historial!$G$3:$G$502,H$4,Historial!$H$3:$H$502,$B$2)>0,"✓","")) | I20: =IF($A19="","",IF(COUNTIFS(Historial!$B$3:$B$502,$A19,Historial!$C$3:$C$502,$B19,Historial!$G$3:$G$502,I$4,Historial!$H$3:$H$502,$B$2)>0,"✓","")) | J20: =IF($A19="","",IF(COUNTIFS(Historial!$B$3:$B$502,$A19,Historial!$C$3:$C$502,$B19,Historial!$G$3:$G$502,J$4,Historial!$H$3:$H$502,$B$2)>0,"✓","")) | K20: =IF($A19="","",IF(COUNTIFS(Historial!$B$3:$B$502,$A19,Historial!$C$3:$C$502,$B19,Historial!$G$3:$G$502,K$4,Historial!$H$3:$H$502,$B$2)>0,"✓","")) | ... BC20: =IF($A19="","",IF(COUNTIFS(Historial!$B$3:$B$502,$A19,Historial!$C$3:$C$502,$B19,Historial!$G$3:$G$502,BC$4,Historial!$H$3:$H$502,$B$2)>0,"✓",""))
A21: =IF(Actividades!$B11="","",Actividades!$B11) | B21: =IF(Actividades!$C11="","",Actividades!$C11) | C21: =IF($A21="","","Plan") | D21: =IF($A21="","",IF(AND(N(Actividades!$E11)>0,D$4>=Actividades!$E11,MOD(D$4-Actividades!$E11,IFERROR(VLOOKUP(Actividades!$D11,Listas!$A$2:$B$8,2,0),52))=0),"P","")) | E21: =IF($A21="","",IF(AND(N(Actividades!$E11)>0,E$4>=Actividades!$E11,MOD(E$4-Actividades!$E11,IFERROR(VLOOKUP(Actividades!$D11,Listas!$A$2:$B$8,2,0),52))=0),"P","")) | F21: =IF($A21="","",IF(AND(N(Actividades!$E11)>0,F$4>=Actividades!$E11,MOD(F$4-Actividades!$E11,IFERROR(VLOOKUP(Actividades!$D11,Listas!$A$2:$B$8,2,0),52))=0),"P","")) | G21: =IF($A21="","",IF(AND(N(Actividades!$E11)>0,G$4>=Actividades!$E11,MOD(G$4-Actividades!$E11,IFERROR(VLOOKUP(Actividades!$D11,Listas!$A$2:$B$8,2,0),52))=0),"P","")) | H21: =IF($A21="","",IF(AND(N(Actividades!$E11)>0,H$4>=Actividades!$E11,MOD(H$4-Actividades!$E11,IFERROR(VLOOKUP(Actividades!$D11,Listas!$A$2:$B$8,2,0),52))=0),"P","")) | I21: =IF($A21="","",IF(AND(N(Actividades!$E11)>0,I$4>=Actividades!$E11,MOD(I$4-Actividades!$E11,IFERROR(VLOOKUP(Actividades!$D11,Listas!$A$2:$B$8,2,0),52))=0),"P","")) | J21: =IF($A21="","",IF(AND(N(Actividades!$E11)>0,J$4>=Actividades!$E11,MOD(J$4-Actividades!$E11,IFERROR(VLOOKUP(Actividades!$D11,Listas!$A$2:$B$8,2,0),52))=0),"P","")) | K21: =IF($A21="","",IF(AND(N(Actividades!$E11)>0,K$4>=Actividades!$E11,MOD(K$4-Actividades!$E11,IFERROR(VLOOKUP(Actividades!$D11,Listas!$A$2:$B$8,2,0),52))=0),"P","")) | ... BC21: =IF($A21="","",IF(AND(N(Actividades!$E11)>0,BC$4>=Actividades!$E11,MOD(BC$4-Actividades!$E11,IFERROR(VLOOKUP(Actividades!$D11,Listas!$A$2:$B$8,2,0),52))=0),"P","")) | BD21: =IF($A21="","",COUNTIF(D21:BC21,"P")) | BE21: =IF($A21="","",SUMPRODUCT((D21:BC21="P")*(D22:BC22="✓"))) | BF21: =IF($A21="","",IF(BD21=0,"",BE21/BD21))
C22: =IF($A21="","","Real") | D22: =IF($A21="","",IF(COUNTIFS(Historial!$B$3:$B$502,$A21,Historial!$C$3:$C$502,$B21,Historial!$G$3:$G$502,D$4,Historial!$H$3:$H$502,$B$2)>0,"✓","")) | E22: =IF($A21="","",IF(COUNTIFS(Historial!$B$3:$B$502,$A21,Historial!$C$3:$C$502,$B21,Historial!$G$3:$G$502,E$4,Historial!$H$3:$H$502,$B$2)>0,"✓","")) | F22: =IF($A21="","",IF(COUNTIFS(Historial!$B$3:$B$502,$A21,Historial!$C$3:$C$502,$B21,Historial!$G$3:$G$502,F$4,Historial!$H$3:$H$502,$B$2)>0,"✓","")) | G22: =IF($A21="","",IF(COUNTIFS(Historial!$B$3:$B$502,$A21,Historial!$C$3:$C$502,$B21,Historial!$G$3:$G$502,G$4,Historial!$H$3:$H$502,$B$2)>0,"✓","")) | H22: =IF($A21="","",IF(COUNTIFS(Historial!$B$3:$B$502,$A21,Historial!$C$3:$C$502,$B21,Historial!$G$3:$G$502,H$4,Historial!$H$3:$H$502,$B$2)>0,"✓","")) | I22: =IF($A21="","",IF(COUNTIFS(Historial!$B$3:$B$502,$A21,Historial!$C$3:$C$502,$B21,Historial!$G$3:$G$502,I$4,Historial!$H$3:$H$502,$B$2)>0,"✓","")) | J22: =IF($A21="","",IF(COUNTIFS(Historial!$B$3:$B$502,$A21,Historial!$C$3:$C$502,$B21,Historial!$G$3:$G$502,J$4,Historial!$H$3:$H$502,$B$2)>0,"✓","")) | K22: =IF($A21="","",IF(COUNTIFS(Historial!$B$3:$B$502,$A21,Historial!$C$3:$C$502,$B21,Historial!$G$3:$G$502,K$4,Historial!$H$3:$H$502,$B$2)>0,"✓","")) | ... BC22: =IF($A21="","",IF(COUNTIFS(Historial!$B$3:$B$502,$A21,Historial!$C$3:$C$502,$B21,Historial!$G$3:$G$502,BC$4,Historial!$H$3:$H$502,$B$2)>0,"✓",""))
A23: =IF(Actividades!$B12="","",Actividades!$B12) | B23: =IF(Actividades!$C12="","",Actividades!$C12) | C23: =IF($A23="","","Plan") | D23: =IF($A23="","",IF(AND(N(Actividades!$E12)>0,D$4>=Actividades!$E12,MOD(D$4-Actividades!$E12,IFERROR(VLOOKUP(Actividades!$D12,Listas!$A$2:$B$8,2,0),52))=0),"P","")) | E23: =IF($A23="","",IF(AND(N(Actividades!$E12)>0,E$4>=Actividades!$E12,MOD(E$4-Actividades!$E12,IFERROR(VLOOKUP(Actividades!$D12,Listas!$A$2:$B$8,2,0),52))=0),"P","")) | F23: =IF($A23="","",IF(AND(N(Actividades!$E12)>0,F$4>=Actividades!$E12,MOD(F$4-Actividades!$E12,IFERROR(VLOOKUP(Actividades!$D12,Listas!$A$2:$B$8,2,0),52))=0),"P","")) | G23: =IF($A23="","",IF(AND(N(Actividades!$E12)>0,G$4>=Actividades!$E12,MOD(G$4-Actividades!$E12,IFERROR(VLOOKUP(Actividades!$D12,Listas!$A$2:$B$8,2,0),52))=0),"P","")) | H23: =IF($A23="","",IF(AND(N(Actividades!$E12)>0,H$4>=Actividades!$E12,MOD(H$4-Actividades!$E12,IFERROR(VLOOKUP(Actividades!$D12,Listas!$A$2:$B$8,2,0),52))=0),"P","")) | I23: =IF($A23="","",IF(AND(N(Actividades!$E12)>0,I$4>=Actividades!$E12,MOD(I$4-Actividades!$E12,IFERROR(VLOOKUP(Actividades!$D12,Listas!$A$2:$B$8,2,0),52))=0),"P","")) | J23: =IF($A23="","",IF(AND(N(Actividades!$E12)>0,J$4>=Actividades!$E12,MOD(J$4-Actividades!$E12,IFERROR(VLOOKUP(Actividades!$D12,Listas!$A$2:$B$8,2,0),52))=0),"P","")) | K23: =IF($A23="","",IF(AND(N(Actividades!$E12)>0,K$4>=Actividades!$E12,MOD(K$4-Actividades!$E12,IFERROR(VLOOKUP(Actividades!$D12,Listas!$A$2:$B$8,2,0),52))=0),"P","")) | ... BC23: =IF($A23="","",IF(AND(N(Actividades!$E12)>0,BC$4>=Actividades!$E12,MOD(BC$4-Actividades!$E12,IFERROR(VLOOKUP(Actividades!$D12,Listas!$A$2:$B$8,2,0),52))=0),"P","")) | BD23: =IF($A23="","",COUNTIF(D23:BC23,"P")) | BE23: =IF($A23="","",SUMPRODUCT((D23:BC23="P")*(D24:BC24="✓"))) | BF23: =IF($A23="","",IF(BD23=0,"",BE23/BD23))
C24: =IF($A23="","","Real") | D24: =IF($A23="","",IF(COUNTIFS(Historial!$B$3:$B$502,$A23,Historial!$C$3:$C$502,$B23,Historial!$G$3:$G$502,D$4,Historial!$H$3:$H$502,$B$2)>0,"✓","")) | E24: =IF($A23="","",IF(COUNTIFS(Historial!$B$3:$B$502,$A23,Historial!$C$3:$C$502,$B23,Historial!$G$3:$G$502,E$4,Historial!$H$3:$H$502,$B$2)>0,"✓","")) | F24: =IF($A23="","",IF(COUNTIFS(Historial!$B$3:$B$502,$A23,Historial!$C$3:$C$502,$B23,Historial!$G$3:$G$502,F$4,Historial!$H$3:$H$502,$B$2)>0,"✓","")) | G24: =IF($A23="","",IF(COUNTIFS(Historial!$B$3:$B$502,$A23,Historial!$C$3:$C$502,$B23,Historial!$G$3:$G$502,G$4,Historial!$H$3:$H$502,$B$2)>0,"✓","")) | H24: =IF($A23="","",IF(COUNTIFS(Historial!$B$3:$B$502,$A23,Historial!$C$3:$C$502,$B23,Historial!$G$3:$G$502,H$4,Historial!$H$3:$H$502,$B$2)>0,"✓","")) | I24: =IF($A23="","",IF(COUNTIFS(Historial!$B$3:$B$502,$A23,Historial!$C$3:$C$502,$B23,Historial!$G$3:$G$502,I$4,Historial!$H$3:$H$502,$B$2)>0,"✓","")) | J24: =IF($A23="","",IF(COUNTIFS(Historial!$B$3:$B$502,$A23,Historial!$C$3:$C$502,$B23,Historial!$G$3:$G$502,J$4,Historial!$H$3:$H$502,$B$2)>0,"✓","")) | K24: =IF($A23="","",IF(COUNTIFS(Historial!$B$3:$B$502,$A23,Historial!$C$3:$C$502,$B23,Historial!$G$3:$G$502,K$4,Historial!$H$3:$H$502,$B$2)>0,"✓","")) | ... BC24: =IF($A23="","",IF(COUNTIFS(Historial!$B$3:$B$502,$A23,Historial!$C$3:$C$502,$B23,Historial!$G$3:$G$502,BC$4,Historial!$H$3:$H$502,$B$2)>0,"✓",""))
A25: =IF(Actividades!$B13="","",Actividades!$B13) | B25: =IF(Actividades!$C13="","",Actividades!$C13) | C25: =IF($A25="","","Plan") | D25: =IF($A25="","",IF(AND(N(Actividades!$E13)>0,D$4>=Actividades!$E13,MOD(D$4-Actividades!$E13,IFERROR(VLOOKUP(Actividades!$D13,Listas!$A$2:$B$8,2,0),52))=0),"P","")) | E25: =IF($A25="","",IF(AND(N(Actividades!$E13)>0,E$4>=Actividades!$E13,MOD(E$4-Actividades!$E13,IFERROR(VLOOKUP(Actividades!$D13,Listas!$A$2:$B$8,2,0),52))=0),"P","")) | F25: =IF($A25="","",IF(AND(N(Actividades!$E13)>0,F$4>=Actividades!$E13,MOD(F$4-Actividades!$E13,IFERROR(VLOOKUP(Actividades!$D13,Listas!$A$2:$B$8,2,0),52))=0),"P","")) | G25: =IF($A25="","",IF(AND(N(Actividades!$E13)>0,G$4>=Actividades!$E13,MOD(G$4-Actividades!$E13,IFERROR(VLOOKUP(Actividades!$D13,Listas!$A$2:$B$8,2,0),52))=0),"P","")) | H25: =IF($A25="","",IF(AND(N(Actividades!$E13)>0,H$4>=Actividades!$E13,MOD(H$4-Actividades!$E13,IFERROR(VLOOKUP(Actividades!$D13,Listas!$A$2:$B$8,2,0),52))=0),"P","")) | I25: =IF($A25="","",IF(AND(N(Actividades!$E13)>0,I$4>=Actividades!$E13,MOD(I$4-Actividades!$E13,IFERROR(VLOOKUP(Actividades!$D13,Listas!$A$2:$B$8,2,0),52))=0),"P","")) | J25: =IF($A25="","",IF(AND(N(Actividades!$E13)>0,J$4>=Actividades!$E13,MOD(J$4-Actividades!$E13,IFERROR(VLOOKUP(Actividades!$D13,Listas!$A$2:$B$8,2,0),52))=0),"P","")) | K25: =IF($A25="","",IF(AND(N(Actividades!$E13)>0,K$4>=Actividades!$E13,MOD(K$4-Actividades!$E13,IFERROR(VLOOKUP(Actividades!$D13,Listas!$A$2:$B$8,2,0),52))=0),"P","")) | ... BC25: =IF($A25="","",IF(AND(N(Actividades!$E13)>0,BC$4>=Actividades!$E13,MOD(BC$4-Actividades!$E13,IFERROR(VLOOKUP(Actividades!$D13,Listas!$A$2:$B$8,2,0),52))=0),"P","")) | BD25: =IF($A25="","",COUNTIF(D25:BC25,"P")) | BE25: =IF($A25="","",SUMPRODUCT((D25:BC25="P")*(D26:BC26="✓"))) | BF25: =IF($A25="","",IF(BD25=0,"",BE25/BD25))
C26: =IF($A25="","","Real") | D26: =IF($A25="","",IF(COUNTIFS(Historial!$B$3:$B$502,$A25,Historial!$C$3:$C$502,$B25,Historial!$G$3:$G$502,D$4,Historial!$H$3:$H$502,$B$2)>0,"✓","")) | E26: =IF($A25="","",IF(COUNTIFS(Historial!$B$3:$B$502,$A25,Historial!$C$3:$C$502,$B25,Historial!$G$3:$G$502,E$4,Historial!$H$3:$H$502,$B$2)>0,"✓","")) | F26: =IF($A25="","",IF(COUNTIFS(Historial!$B$3:$B$502,$A25,Historial!$C$3:$C$502,$B25,Historial!$G$3:$G$502,F$4,Historial!$H$3:$H$502,$B$2)>0,"✓","")) | G26: =IF($A25="","",IF(COUNTIFS(Historial!$B$3:$B$502,$A25,Historial!$C$3:$C$502,$B25,Historial!$G$3:$G$502,G$4,Historial!$H$3:$H$502,$B$2)>0,"✓","")) | H26: =IF($A25="","",IF(COUNTIFS(Historial!$B$3:$B$502,$A25,Historial!$C$3:$C$502,$B25,Historial!$G$3:$G$502,H$4,Historial!$H$3:$H$502,$B$2)>0,"✓","")) | I26: =IF($A25="","",IF(COUNTIFS(Historial!$B$3:$B$502,$A25,Historial!$C$3:$C$502,$B25,Historial!$G$3:$G$502,I$4,Historial!$H$3:$H$502,$B$2)>0,"✓","")) | J26: =IF($A25="","",IF(COUNTIFS(Historial!$B$3:$B$502,$A25,Historial!$C$3:$C$502,$B25,Historial!$G$3:$G$502,J$4,Historial!$H$3:$H$502,$B$2)>0,"✓","")) | K26: =IF($A25="","",IF(COUNTIFS(Historial!$B$3:$B$502,$A25,Historial!$C$3:$C$502,$B25,Historial!$G$3:$G$502,K$4,Historial!$H$3:$H$502,$B$2)>0,"✓","")) | ... BC26: =IF($A25="","",IF(COUNTIFS(Historial!$B$3:$B$502,$A25,Historial!$C$3:$C$502,$B25,Historial!$G$3:$G$502,BC$4,Historial!$H$3:$H$502,$B$2)>0,"✓",""))
A27: =IF(Actividades!$B14="","",Actividades!$B14) | B27: =IF(Actividades!$C14="","",Actividades!$C14) | C27: =IF($A27="","","Plan") | D27: =IF($A27="","",IF(AND(N(Actividades!$E14)>0,D$4>=Actividades!$E14,MOD(D$4-Actividades!$E14,IFERROR(VLOOKUP(Actividades!$D14,Listas!$A$2:$B$8,2,0),52))=0),"P","")) | E27: =IF($A27="","",IF(AND(N(Actividades!$E14)>0,E$4>=Actividades!$E14,MOD(E$4-Actividades!$E14,IFERROR(VLOOKUP(Actividades!$D14,Listas!$A$2:$B$8,2,0),52))=0),"P","")) | F27: =IF($A27="","",IF(AND(N(Actividades!$E14)>0,F$4>=Actividades!$E14,MOD(F$4-Actividades!$E14,IFERROR(VLOOKUP(Actividades!$D14,Listas!$A$2:$B$8,2,0),52))=0),"P","")) | G27: =IF($A27="","",IF(AND(N(Actividades!$E14)>0,G$4>=Actividades!$E14,MOD(G$4-Actividades!$E14,IFERROR(VLOOKUP(Actividades!$D14,Listas!$A$2:$B$8,2,0),52))=0),"P","")) | H27: =IF($A27="","",IF(AND(N(Actividades!$E14)>0,H$4>=Actividades!$E14,MOD(H$4-Actividades!$E14,IFERROR(VLOOKUP(Actividades!$D14,Listas!$A$2:$B$8,2,0),52))=0),"P","")) | I27: =IF($A27="","",IF(AND(N(Actividades!$E14)>0,I$4>=Actividades!$E14,MOD(I$4-Actividades!$E14,IFERROR(VLOOKUP(Actividades!$D14,Listas!$A$2:$B$8,2,0),52))=0),"P","")) | J27: =IF($A27="","",IF(AND(N(Actividades!$E14)>0,J$4>=Actividades!$E14,MOD(J$4-Actividades!$E14,IFERROR(VLOOKUP(Actividades!$D14,Listas!$A$2:$B$8,2,0),52))=0),"P","")) | K27: =IF($A27="","",IF(AND(N(Actividades!$E14)>0,K$4>=Actividades!$E14,MOD(K$4-Actividades!$E14,IFERROR(VLOOKUP(Actividades!$D14,Listas!$A$2:$B$8,2,0),52))=0),"P","")) | ... BC27: =IF($A27="","",IF(AND(N(Actividades!$E14)>0,BC$4>=Actividades!$E14,MOD(BC$4-Actividades!$E14,IFERROR(VLOOKUP(Actividades!$D14,Listas!$A$2:$B$8,2,0),52))=0),"P","")) | BD27: =IF($A27="","",COUNTIF(D27:BC27,"P")) | BE27: =IF($A27="","",SUMPRODUCT((D27:BC27="P")*(D28:BC28="✓"))) | BF27: =IF($A27="","",IF(BD27=0,"",BE27/BD27))
C28: =IF($A27="","","Real") | D28: =IF($A27="","",IF(COUNTIFS(Historial!$B$3:$B$502,$A27,Historial!$C$3:$C$502,$B27,Historial!$G$3:$G$502,D$4,Historial!$H$3:$H$502,$B$2)>0,"✓","")) | E28: =IF($A27="","",IF(COUNTIFS(Historial!$B$3:$B$502,$A27,Historial!$C$3:$C$502,$B27,Historial!$G$3:$G$502,E$4,Historial!$H$3:$H$502,$B$2)>0,"✓","")) | F28: =IF($A27="","",IF(COUNTIFS(Historial!$B$3:$B$502,$A27,Historial!$C$3:$C$502,$B27,Historial!$G$3:$G$502,F$4,Historial!$H$3:$H$502,$B$2)>0,"✓","")) | G28: =IF($A27="","",IF(COUNTIFS(Historial!$B$3:$B$502,$A27,Historial!$C$3:$C$502,$B27,Historial!$G$3:$G$502,G$4,Historial!$H$3:$H$502,$B$2)>0,"✓","")) | H28: =IF($A27="","",IF(COUNTIFS(Historial!$B$3:$B$502,$A27,Historial!$C$3:$C$502,$B27,Historial!$G$3:$G$502,H$4,Historial!$H$3:$H$502,$B$2)>0,"✓","")) | I28: =IF($A27="","",IF(COUNTIFS(Historial!$B$3:$B$502,$A27,Historial!$C$3:$C$502,$B27,Historial!$G$3:$G$502,I$4,Historial!$H$3:$H$502,$B$2)>0,"✓","")) | J28: =IF($A27="","",IF(COUNTIFS(Historial!$B$3:$B$502,$A27,Historial!$C$3:$C$502,$B27,Historial!$G$3:$G$502,J$4,Historial!$H$3:$H$502,$B$2)>0,"✓","")) | K28: =IF($A27="","",IF(COUNTIFS(Historial!$B$3:$B$502,$A27,Historial!$C$3:$C$502,$B27,Historial!$G$3:$G$502,K$4,Historial!$H$3:$H$502,$B$2)>0,"✓","")) | ... BC28: =IF($A27="","",IF(COUNTIFS(Historial!$B$3:$B$502,$A27,Historial!$C$3:$C$502,$B27,Historial!$G$3:$G$502,BC$4,Historial!$H$3:$H$502,$B$2)>0,"✓",""))
A29: =IF(Actividades!$B15="","",Actividades!$B15) | B29: =IF(Actividades!$C15="","",Actividades!$C15) | C29: =IF($A29="","","Plan") | D29: =IF($A29="","",IF(AND(N(Actividades!$E15)>0,D$4>=Actividades!$E15,MOD(D$4-Actividades!$E15,IFERROR(VLOOKUP(Actividades!$D15,Listas!$A$2:$B$8,2,0),52))=0),"P","")) | E29: =IF($A29="","",IF(AND(N(Actividades!$E15)>0,E$4>=Actividades!$E15,MOD(E$4-Actividades!$E15,IFERROR(VLOOKUP(Actividades!$D15,Listas!$A$2:$B$8,2,0),52))=0),"P","")) | F29: =IF($A29="","",IF(AND(N(Actividades!$E15)>0,F$4>=Actividades!$E15,MOD(F$4-Actividades!$E15,IFERROR(VLOOKUP(Actividades!$D15,Listas!$A$2:$B$8,2,0),52))=0),"P","")) | G29: =IF($A29="","",IF(AND(N(Actividades!$E15)>0,G$4>=Actividades!$E15,MOD(G$4-Actividades!$E15,IFERROR(VLOOKUP(Actividades!$D15,Listas!$A$2:$B$8,2,0),52))=0),"P","")) | H29: =IF($A29="","",IF(AND(N(Actividades!$E15)>0,H$4>=Actividades!$E15,MOD(H$4-Actividades!$E15,IFERROR(VLOOKUP(Actividades!$D15,Listas!$A$2:$B$8,2,0),52))=0),"P","")) | I29: =IF($A29="","",IF(AND(N(Actividades!$E15)>0,I$4>=Actividades!$E15,MOD(I$4-Actividades!$E15,IFERROR(VLOOKUP(Actividades!$D15,Listas!$A$2:$B$8,2,0),52))=0),"P","")) | J29: =IF($A29="","",IF(AND(N(Actividades!$E15)>0,J$4>=Actividades!$E15,MOD(J$4-Actividades!$E15,IFERROR(VLOOKUP(Actividades!$D15,Listas!$A$2:$B$8,2,0),52))=0),"P","")) | K29: =IF($A29="","",IF(AND(N(Actividades!$E15)>0,K$4>=Actividades!$E15,MOD(K$4-Actividades!$E15,IFERROR(VLOOKUP(Actividades!$D15,Listas!$A$2:$B$8,2,0),52))=0),"P","")) | ... BC29: =IF($A29="","",IF(AND(N(Actividades!$E15)>0,BC$4>=Actividades!$E15,MOD(BC$4-Actividades!$E15,IFERROR(VLOOKUP(Actividades!$D15,Listas!$A$2:$B$8,2,0),52))=0),"P","")) | BD29: =IF($A29="","",COUNTIF(D29:BC29,"P")) | BE29: =IF($A29="","",SUMPRODUCT((D29:BC29="P")*(D30:BC30="✓"))) | BF29: =IF($A29="","",IF(BD29=0,"",BE29/BD29))
C30: =IF($A29="","","Real") | D30: =IF($A29="","",IF(COUNTIFS(Historial!$B$3:$B$502,$A29,Historial!$C$3:$C$502,$B29,Historial!$G$3:$G$502,D$4,Historial!$H$3:$H$502,$B$2)>0,"✓","")) | E30: =IF($A29="","",IF(COUNTIFS(Historial!$B$3:$B$502,$A29,Historial!$C$3:$C$502,$B29,Historial!$G$3:$G$502,E$4,Historial!$H$3:$H$502,$B$2)>0,"✓","")) | F30: =IF($A29="","",IF(COUNTIFS(Historial!$B$3:$B$502,$A29,Historial!$C$3:$C$502,$B29,Historial!$G$3:$G$502,F$4,Historial!$H$3:$H$502,$B$2)>0,"✓","")) | G30: =IF($A29="","",IF(COUNTIFS(Historial!$B$3:$B$502,$A29,Historial!$C$3:$C$502,$B29,Historial!$G$3:$G$502,G$4,Historial!$H$3:$H$502,$B$2)>0,"✓","")) | H30: =IF($A29="","",IF(COUNTIFS(Historial!$B$3:$B$502,$A29,Historial!$C$3:$C$502,$B29,Historial!$G$3:$G$502,H$4,Historial!$H$3:$H$502,$B$2)>0,"✓","")) | I30: =IF($A29="","",IF(COUNTIFS(Historial!$B$3:$B$502,$A29,Historial!$C$3:$C$502,$B29,Historial!$G$3:$G$502,I$4,Historial!$H$3:$H$502,$B$2)>0,"✓","")) | J30: =IF($A29="","",IF(COUNTIFS(Historial!$B$3:$B$502,$A29,Historial!$C$3:$C$502,$B29,Historial!$G$3:$G$502,J$4,Historial!$H$3:$H$502,$B$2)>0,"✓","")) | K30: =IF($A29="","",IF(COUNTIFS(Historial!$B$3:$B$502,$A29,Historial!$C$3:$C$502,$B29,Historial!$G$3:$G$502,K$4,Historial!$H$3:$H$502,$B$2)>0,"✓","")) | ... BC30: =IF($A29="","",IF(COUNTIFS(Historial!$B$3:$B$502,$A29,Historial!$C$3:$C$502,$B29,Historial!$G$3:$G$502,BC$4,Historial!$H$3:$H$502,$B$2)>0,"✓",""))
A31: =IF(Actividades!$B16="","",Actividades!$B16) | B31: =IF(Actividades!$C16="","",Actividades!$C16) | C31: =IF($A31="","","Plan") | D31: =IF($A31="","",IF(AND(N(Actividades!$E16)>0,D$4>=Actividades!$E16,MOD(D$4-Actividades!$E16,IFERROR(VLOOKUP(Actividades!$D16,Listas!$A$2:$B$8,2,0),52))=0),"P","")) | E31: =IF($A31="","",IF(AND(N(Actividades!$E16)>0,E$4>=Actividades!$E16,MOD(E$4-Actividades!$E16,IFERROR(VLOOKUP(Actividades!$D16,Listas!$A$2:$B$8,2,0),52))=0),"P","")) | F31: =IF($A31="","",IF(AND(N(Actividades!$E16)>0,F$4>=Actividades!$E16,MOD(F$4-Actividades!$E16,IFERROR(VLOOKUP(Actividades!$D16,Listas!$A$2:$B$8,2,0),52))=0),"P","")) | G31: =IF($A31="","",IF(AND(N(Actividades!$E16)>0,G$4>=Actividades!$E16,MOD(G$4-Actividades!$E16,IFERROR(VLOOKUP(Actividades!$D16,Listas!$A$2:$B$8,2,0),52))=0),"P","")) | H31: =IF($A31="","",IF(AND(N(Actividades!$E16)>0,H$4>=Actividades!$E16,MOD(H$4-Actividades!$E16,IFERROR(VLOOKUP(Actividades!$D16,Listas!$A$2:$B$8,2,0),52))=0),"P","")) | I31: =IF($A31="","",IF(AND(N(Actividades!$E16)>0,I$4>=Actividades!$E16,MOD(I$4-Actividades!$E16,IFERROR(VLOOKUP(Actividades!$D16,Listas!$A$2:$B$8,2,0),52))=0),"P","")) | J31: =IF($A31="","",IF(AND(N(Actividades!$E16)>0,J$4>=Actividades!$E16,MOD(J$4-Actividades!$E16,IFERROR(VLOOKUP(Actividades!$D16,Listas!$A$2:$B$8,2,0),52))=0),"P","")) | K31: =IF($A31="","",IF(AND(N(Actividades!$E16)>0,K$4>=Actividades!$E16,MOD(K$4-Actividades!$E16,IFERROR(VLOOKUP(Actividades!$D16,Listas!$A$2:$B$8,2,0),52))=0),"P","")) | ... BC31: =IF($A31="","",IF(AND(N(Actividades!$E16)>0,BC$4>=Actividades!$E16,MOD(BC$4-Actividades!$E16,IFERROR(VLOOKUP(Actividades!$D16,Listas!$A$2:$B$8,2,0),52))=0),"P","")) | BD31: =IF($A31="","",COUNTIF(D31:BC31,"P")) | BE31: =IF($A31="","",SUMPRODUCT((D31:BC31="P")*(D32:BC32="✓"))) | BF31: =IF($A31="","",IF(BD31=0,"",BE31/BD31))
C32: =IF($A31="","","Real") | D32: =IF($A31="","",IF(COUNTIFS(Historial!$B$3:$B$502,$A31,Historial!$C$3:$C$502,$B31,Historial!$G$3:$G$502,D$4,Historial!$H$3:$H$502,$B$2)>0,"✓","")) | E32: =IF($A31="","",IF(COUNTIFS(Historial!$B$3:$B$502,$A31,Historial!$C$3:$C$502,$B31,Historial!$G$3:$G$502,E$4,Historial!$H$3:$H$502,$B$2)>0,"✓","")) | F32: =IF($A31="","",IF(COUNTIFS(Historial!$B$3:$B$502,$A31,Historial!$C$3:$C$502,$B31,Historial!$G$3:$G$502,F$4,Historial!$H$3:$H$502,$B$2)>0,"✓","")) | G32: =IF($A31="","",IF(COUNTIFS(Historial!$B$3:$B$502,$A31,Historial!$C$3:$C$502,$B31,Historial!$G$3:$G$502,G$4,Historial!$H$3:$H$502,$B$2)>0,"✓","")) | H32: =IF($A31="","",IF(COUNTIFS(Historial!$B$3:$B$502,$A31,Historial!$C$3:$C$502,$B31,Historial!$G$3:$G$502,H$4,Historial!$H$3:$H$502,$B$2)>0,"✓","")) | I32: =IF($A31="","",IF(COUNTIFS(Historial!$B$3:$B$502,$A31,Historial!$C$3:$C$502,$B31,Historial!$G$3:$G$502,I$4,Historial!$H$3:$H$502,$B$2)>0,"✓","")) | J32: =IF($A31="","",IF(COUNTIFS(Historial!$B$3:$B$502,$A31,Historial!$C$3:$C$502,$B31,Historial!$G$3:$G$502,J$4,Historial!$H$3:$H$502,$B$2)>0,"✓","")) | K32: =IF($A31="","",IF(COUNTIFS(Historial!$B$3:$B$502,$A31,Historial!$C$3:$C$502,$B31,Historial!$G$3:$G$502,K$4,Historial!$H$3:$H$502,$B$2)>0,"✓","")) | ... BC32: =IF($A31="","",IF(COUNTIFS(Historial!$B$3:$B$502,$A31,Historial!$C$3:$C$502,$B31,Historial!$G$3:$G$502,BC$4,Historial!$H$3:$H$502,$B$2)>0,"✓",""))
